<?xml version="1.0"?>
<robot
  xmlns:xacro="http://ros.org/wiki/xacro"
  xmlns:controller="http://playerstage.sourceforge.net/gazebo/xmlschema/#controller"
  xmlns:interface="http://playerstage.sourceforge.net/gazebo/xmlschema/#interface"
  xmlns:sensor="http://playerstage.sourceforge.net/gazebo/xmlschema/#sensor"
  name="robot_sensor">

<xacro:property name="M_PI" value="3.14159265359"/>

<link name="base_footprint">
</link>

<link name="base_link">
  <visual>
    <origin xyz="0 0 0" rpy="0 0 0" />
    <geometry>
      <box size="0.4 0.3 0.2"/>
    </geometry>
    <material name="silver" >
      <color rgba="0.5 0.5 0.5 1" />
    </material>
  </visual>
  <collision>
    <origin xyz="0 0 0" rpy="0 0 0" />
    <geometry>
      <box size="0.4 0.3 0.2"/>
    </geometry>
  </collision>
  <inertial>
      <mass value="10.0" />
      <origin xyz="0 0 0" />
      <inertia ixx="${0.0833333 * 10.0 * (0.3*0.3 + 0.2*0.2)}" ixy="0.0" ixz="0.0"
        iyy="${0.0833333 * 10.0 * (0.4*0.4 + 0.2*0.2)}" iyz="0.0"
        izz="${0.0833333 * 10.0 * (0.4*0.4 + 0.3*0.3)}" />
    </inertial>
</link>

<joint name="base_to_bf_joint" type="fixed">
  <parent link="base_footprint" />
  <child link="base_link" />
  <origin xyz="0 0 0.1" />
</joint>

<!-- 2D  Rotating LASER -->
<link name="laser2d">
  <collision>
    <origin xyz="0.0 0.0 0.0" rpy="0 0 0"/>
    <geometry>
      <cylinder radius="0.0516" length="0.0717"/>
    </geometry>
  </collision>
  <visual>
    <origin xyz="0 0 0.0" rpy="0 0 0" />
    <geometry>
      <cylinder radius="0.0516" length="0.0717"/>
    </geometry>
  </visual>
  <inertial>
    <mass value="0.83"/>
    <origin xyz="0 0 0.0"/>
    <inertia ixx="${(0.83 * (3.0*0.0516*0.0516 + 0.0717*0.0717)) / 12.0}" ixy="0" ixz="0"
      iyy="${(0.83 * (3.0*0.0516*0.0516 + 0.0717*0.0717)) / 12.0}" iyz="0"
      izz="${0.5 * 0.83 * (0.0516*0.0516)}"/>
  </inertial>
</link>

<gazebo reference="laser2d">
  <rmagine_ignore/>
</gazebo>

<joint name="laser2d_to_base_joint" type="continuous">
  <parent link="base_link" />
  <child link="laser2d" />
  <origin xyz="0 0 0.5" rpy="${M_PI/2.0} 0.0 0.0" />
  <axis xyz="0 1 0"/>
</joint>

<gazebo reference="laser2d">
    <sensor type="rmagine_embree_spherical" name="laser2d">
      <pose>0 0 0 0 0 0</pose>
      <always_on>true</always_on>
      <update_rate>60</update_rate>

      <ray>
        <scan>
          <horizontal>
            <min_angle>${-60.0 * M_PI / 180.0}</min_angle>
            <increment>${0.01 * M_PI / 180.0}</increment>
            <samples>12000</samples>
          </horizontal>
        </scan>

        <range>
          <min>0.2</min>
          <max>100.0</max>
        </range>

      </ray>

      <plugin name="rmagine_ros_laser3d" filename="librmagine_embree_ros_gzplugin.so">
          <frame>laser2d</frame>

          <outputs>
            <output name="scan">
              <msg>sensor_msgs/LaserScan</msg>
              <topic>laser2d/scan</topic>
            </output>

            <output name="pcl">
              <msg>sensor_msgs/PointCloud</msg>
              <topic>laser2d/pcl</topic>
            </output>

          </outputs>
      </plugin>
    </sensor>
</gazebo>

<gazebo>
  <plugin name="joint_state_publisher" filename="libgazebo_ros_joint_state_publisher.so">
      <!-- <robotNamespace>/mm</robotNamespace> -->
      <jointName>
        robot_sensor::laser2d_to_base_joint
      </jointName>
  </plugin>    
</gazebo>

</robot>